Workbook

Sheet Original Dataset
A1: Region | B1: Country | C1: Item Type | D1: Sales Channel | E1: Order Priority | F1: Order Date | G1: Order ID | H1: Ship Date | I1: Units Sold | J1: Unit Price | K1: Unit Cost | L1: Total Revenue | M1: Total Cost | N1: Total Profit
A2: Australia and Oceania | B2: Tuvalu | C2: Baby Food | D2: Offline | E2: H | F2: 40326 | G2: 669165933 | H2: 40356 | I2: 9925 | J2: 255.28 | K2: 159.42 | L2: 2533654 | M2: 1582243.5 | N2: 951410.5
A3: Central America and the Caribbean | B3: Grenada | C3: Cereal | D3: Online | E3: C | F3: 41143 | G3: 963881480 | H3: 41167 | I3: 2804 | J3: 205.7 | K3: 117.11 | L3: 576782.8 | M3: 328376.44 | N3: 248406.36
A4: Europe | B4: Russia | C4: Office Supplies | D4: Offline | E4: L | F4: 41761 | G4: 341417157 | H4: 41767 | I4: 1779 | J4: 651.21 | K4: 524.96 | L4: 1158502.6 | M4: 933903.84 | N4: 224598.75
A5: Sub-Saharan Africa | B5: Sao Tome and Principe | C5: Fruits | D5: Online | E5: C | F5: 41810 | G5: 514321792 | H5: 41825 | I5: 8102 | J5: 9.33 | K5: 6.92 | L5: 75591.66 | M5: 56065.84 | N5: 19525.82
A6: Sub-Saharan Africa | B6: Rwanda | C6: Office Supplies | D6: Offline | E6: L | F6: 41306 | G6: 115456712 | H6: 41311 | I6: 5062 | J6: 651.21 | K6: 524.96 | L6: 3296425 | M6: 2657347.5 | N6: 639077.5
A7: Australia and Oceania | B7: Solomon Islands | C7: Baby Food | D7: Online | E7: C | F7: 42039 | G7: 547995746 | H7: 42056 | I7: 2974 | J7: 255.28 | K7: 159.42 | L7: 759202.72 | M7: 474115.08 | N7: 285087.64
A8: Sub-Saharan Africa | B8: Angola | C8: Household | D8: Offline | E8: M | F8: 40656 | G8: 135425221 | H8: 40660 | I8: 4187 | J8: 668.27 | K8: 502.54 | L8: 2798046.5 | M8: 2104135 | N8: 693911.51
A9: Sub-Saharan Africa | B9: Burkina Faso | C9: Vegetables | D9: Online | E9: H | F9: 41107 | G9: 871543967 | H9: 41117 | I9: 8082 | J9: 154.06 | K9: 90.93 | L9: 1245112.9 | M9: 734896.26 | N9: 510216.66
A10: Sub-Saharan Africa | B10: Republic of the Congo | C10: Personal Care | D10: Offline | E10: M | F10: 42199 | G10: 770463311 | H10: 42241 | I10: 6070 | J10: 81.73 | K10: 56.67 | L10: 496101.1 | M10: 343986.9 | N10: 152114.2
A11: Sub-Saharan Africa | B11: Senegal | C11: Cereal | D11: Online | E11: H | F11: 41747 | G11: 616607081 | H11: 41789 | I11: 6593 | J11: 205.7 | K11: 117.11 | L11: 1356180.1 | M11: 772106.23 | N11: 584073.87
A12: Asia | B12: Kyrgyzstan | C12: Vegetables | D12: Online | E12: H | F12: 40718 | G12: 814711606 | H12: 40736 | I12: 124 | J12: 154.06 | K12: 90.93 | L12: 19103.44 | M12: 11275.32 | N12: 7828.12
A13: Sub-Saharan Africa | B13: Cape Verde | C13: Clothes | D13: Offline | E13: H | F13: 41853 | G13: 939825713 | H13: 41870 | I13: 4168 | J13: 109.28 | K13: 35.84 | L13: 455479.04 | M13: 149381.12 | N13: 306097.92
... A101: Sub-Saharan Africa | B101: Mozambique | C101: Household | D101: Offline | E101: L | F101: 40949 | G101: 665095412 | H101: 40954 | I101: 5367 | J101: 668.27 | K101: 502.54 | L101: 3586605.1 | M101: 2697132.2 | N101: 889472.91

Sheet Sample_Sales Records
A1: Region | B1: Country | C1: Item Type | D1: Sales Channel | E1: Order Priority | F1: Order Date | G1: Order ID | H1: Ship Date | I1: Order Year | J1: Order month (Figure) | K1: Order month | L1: Days to ship | M1: Units Sold | N1: Unit Price | O1: Unit Cost | P1: Total Revenue | Q1: Total Cost | R1: Total Profit
A2: Australia and Oceania | B2: Tuvalu | C2: Baby Food | D2: offline | E2: High | F2: 40326 | G2: 669165933 | H2: 40356 | I2: =YEAR(F2) -> 2010 | J2: =MONTH(F2) -> 5 | K2: =TEXT(F2,"mmm") -> May | L2: =H2-F2 -> 30 | M2: 9925 | N2: 255.28 | O2: 159.42 | P2: 2533654 | Q2: 1582243.5 | R2: 951410.5
A3: Central America and the Caribbean | B3: Grenada | C3: Cereal | D3: online | E3: Critical | F3: 41143 | G3: 963881480 | H3: 41167 | I3: =YEAR(F3) -> 2012 | J3: =MONTH(F3) -> 8 | K3: =TEXT(F3,"mmm") -> Aug | L3: =H3-F3 -> 24 | M3: 2804 | N3: 205.7 | O3: 117.11 | P3: 576782.8 | Q3: 328376.44 | R3: 248406.36
A4: Europe | B4: Russia | C4: Office Supplies | D4: offline | E4: Low | F4: 41761 | G4: 341417157 | H4: 41767 | I4: =YEAR(F4) -> 2014 | J4: =MONTH(F4) -> 5 | K4: =TEXT(F4,"mmm") -> May | L4: =H4-F4 -> 6 | M4: 1779 | N4: 651.21 | O4: 524.96 | P4: 1158502.6 | Q4: 933903.84 | R4: 224598.75
A5: Sub-Saharan Africa | B5: Sao Tome and Principe | C5: Fruits | D5: online | E5: Critical | F5: 41810 | G5: 514321792 | H5: 41825 | I5: =YEAR(F5) -> 2014 | J5: =MONTH(F5) -> 6 | K5: =TEXT(F5,"mmm") -> Jun | L5: =H5-F5 -> 15 | M5: 8102 | N5: 9.33 | O5: 6.92 | P5: 75591.66 | Q5: 56065.84 | R5: 19525.82
A6: Sub-Saharan Africa | B6: Rwanda | C6: Office Supplies | D6: offline | E6: Low | F6: 41306 | G6: 115456712 | H6: 41311 | I6: =YEAR(F6) -> 2013 | J6: =MONTH(F6) -> 2 | K6: =TEXT(F6,"mmm") -> Feb | L6: =H6-F6 -> 5 | M6: 5062 | N6: 651.21 | O6: 524.96 | P6: 3296425 | Q6: 2657347.5 | R6: 639077.5
A7: Australia and Oceania | B7: Solomon Islands | C7: Baby Food | D7: online | E7: Critical | F7: 42039 | G7: 547995746 | H7: 42056 | I7: =YEAR(F7) -> 2015 | J7: =MONTH(F7) -> 2 | K7: =TEXT(F7,"mmm") -> Feb | L7: =H7-F7 -> 17 | M7: 2974 | N7: 255.28 | O7: 159.42 | P7: 759202.72 | Q7: 474115.08 | R7: 285087.64
A8: Sub-Saharan Africa | B8: Angola | C8: Household | D8: offline | E8: Medium | F8: 40656 | G8: 135425221 | H8: 40660 | I8: =YEAR(F8) -> 2011 | J8: =MONTH(F8) -> 4 | K8: =TEXT(F8,"mmm") -> Apr | L8: =H8-F8 -> 4 | M8: 4187 | N8: 668.27 | O8: 502.54 | P8: 2798046.5 | Q8: 2104135 | R8: 693911.51
A9: Sub-Saharan Africa | B9: Burkina Faso | C9: Vegetables | D9: online | E9: High | F9: 41107 | G9: 871543967 | H9: 41117 | I9: =YEAR(F9) -> 2012 | J9: =MONTH(F9) -> 7 | K9: =TEXT(F9,"mmm") -> Jul | L9: =H9-F9 -> 10 | M9: 8082 | N9: 154.06 | O9: 90.93 | P9: 1245112.9 | Q9: 734896.26 | R9: 510216.66
A10: Sub-Saharan Africa | B10: Republic of the Congo | C10: Personal Care | D10: offline | E10: Medium | F10: 42199 | G10: 770463311 | H10: 42241 | I10: =YEAR(F10) -> 2015 | J10: =MONTH(F10) -> 7 | K10: =TEXT(F10,"mmm") -> Jul | L10: =H10-F10 -> 42 | M10: 6070 | N10: 81.73 | O10: 56.67 | P10: 496101.1 | Q10: 343986.9 | R10: 152114.2
A11: Sub-Saharan Africa | B11: Senegal | C11: Cereal | D11: online | E11: High | F11: 41747 | G11: 616607081 | H11: 41789 | I11: =YEAR(F11) -> 2014 | J11: =MONTH(F11) -> 4 | K11: =TEXT(F11,"mmm") -> Apr | L11: =H11-F11 -> 42 | M11: 6593 | N11: 205.7 | O11: 117.11 | P11: 1356180.1 | Q11: 772106.23 | R11: 584073.87
A12: Asia | B12: Kyrgyzstan | C12: Vegetables | D12: online | E12: High | F12: 40718 | G12: 814711606 | H12: 40736 | I12: =YEAR(F12) -> 2011 | J12: =MONTH(F12) -> 6 | K12: =TEXT(F12,"mmm") -> Jun | L12: =H12-F12 -> 18 | M12: 124 | N12: 154.06 | O12: 90.93 | P12: 19103.44 | Q12: 11275.32 | R12: 7828.12
A13: Sub-Saharan Africa | B13: Cape Verde | C13: Clothes | D13: offline | E13: High | F13: 41853 | G13: 939825713 | H13: 41870 | I13: =YEAR(F13) -> 2014 | J13: =MONTH(F13) -> 8 | K13: =TEXT(F13,"mmm") -> Aug | L13: =H13-F13 -> 17 | M13: 4168 | N13: 109.28 | O13: 35.84 | P13: 455479.04 | Q13: 149381.12 | R13: 306097.92
... A101: Sub-Saharan Africa | B101: Mozambique | C101: Household | D101: offline | E101: Low | F101: 40949 | G101: 665095412 | H101: 40954 | I101: =YEAR(F101) -> 2012 | J101: =MONTH(F101) -> 2 | K101: =TEXT(F101,"mmm") -> Feb | L101: =H101-F101 -> 5 | M101: 5367 | N101: 668.27 | O101: 502.54 | P101: 3586605.1 | Q101: 2697132.2 | R101: 889472.91

Sheet Issues Log
A1: Columns | B1: Issues | C1: Row Count | D1: Magnitude | E1: Solvable | F1: Resolution
A2: Order priority | B2: Unknow letters | C2: 100 | D2: =C2/100 -> 1 | E2: Y | F2: Requested and obtained more context for the dataset, implemented change using find & replace.
A3: Order date | B3: Complicated data type | C3: 100 | D3: =C3/100 -> 1 | E3: Y | F3: Updated data type to correct format
A4: Ship date | B4: Complicated data type | C4: 100 | D4: =C4/100 -> 1 | E4: Y | F4: Updated data type to correct format
A5: Sales Channel | B5: Casing | C5: 100 | D5: =C5/100 -> 1 | E5: Y | F5: Corrected casing for column using LOWER function
A6: Unit sold | B6: Misleading column name and content | C6: 100 | D6: =C6/100 -> 1 | E6: Y | F6: Updated data type to correct format
A7: Unit Price | B7: Misleading column name and content | C7: 100 | D7: =C7/100 -> 1 | E7: Y | F7: Updated data type to correct format
A8: Total Revenue | B8: Misleading column name and content | C8: 100 | D8: =C8/100 -> 1 | E8: Y | F8: Updated data type to correct format
A9: Total Cost | B9: Misleading column name and content | C9: 100 | D9: =C9/100 -> 1 | E9: Y | F9: Updated data type to correct format
A10: Total Profit | B10: Misleading column name and content | C10: 100 | D10: =C10/100 -> 1 | E10: Y | F10: Updated data type to correct format
A11: Augmentation | B11: Added columns "order year, order month, Days to ship" | C11: 100 | E11: - | F11: Using formulas; YEAR, MONTH, TEXT, and SUBTRACTION, I computed the order year, month and days to ship

Sheet Data Summary (Pivot Table)
D1: Digital Echos Sales Performancae Report
A3: Q1: Revenue and Profit total By Regions
A4: Region | B4: Revenue Total | C4: Profit Total | I4: Q3: Total Items Sold Year By Year
A5: Sub-Saharan Africa | B5: 39672031 | C5: 12183211 | I5: Total Units Sold | J5: Item Type
A6: Europe | B6: 33368932 | C6: 11082939 | I6: Order Year | J6: Baby Food | K6: Beverages | L6: Cereal | M6: Clothes | N6: Cosmetics | O6: Fruits | P6: Household | Q6: Meat | R6: Office Supplies | S6: Personal Care | T6: Snacks | U6: Vegetables | V6: Grand Total
A7: Asia | B7: 21347091 | C7: 6113845.9 | I7: 2010 | J7: 9925 | M7: 18290 | N7: 15144 | O7: 5822 | P7: 3830 | R7: 8287 | S7: 273 | V7: 61571
A8: Australia and Oceania | B8: 14094265 | C8: 4722160 | I8: 2011 | K8: 22726 | M8: 888 | O8: 10051 | P8: 4187 | R8: 8975 | T8: 4085 | U8: 3856 | V8: 54768
A9: Middle East and North Africa | B9: 14052707 | C9: 5761191.9 | I9: 2012 | J9: 8614 | L9: 4921 | M9: 13039 | N9: 8661 | O9: 522 | P9: 12532 | Q9: 5908 | R9: 13982 | S9: 15078 | U9: 14710 | V9: 97967
A10: Central America and the Caribbean | B10: 9170385.5 | C10: 2846907.9 | I10: 2013 | J10: 4750 | L10: 4745 | N10: 25728 | O10: 17243 | R10: 10072 | S10: 2125 | V10: 64663
A11: North America | B11: 5643356.6 | C11: 1457942.8 | I11: 2014 | J11: 13009 | K11: 23892 | L11: 6593 | M11: 12010 | N11: 7215 | O11: 15687 | P11: 6954 | R11: 1779 | S11: 4901 | V11: 92040
A12: Grand Total | B12: 1.3734877e+08 | C12: 44168198 | I12: 2015 | J12: 4247 | K12: 5430 | M12: 13272 | N12: 2847 | O12: 673 | P12: 8250 | R12: 2924 | S12: 11837 | V12: 49480
I13: 2016 | K13: 4660 | L13: 962 | M13: 5498 | N13: 22308 | R13: 948 | S13: 5070 | T13: 2225 | U13: 1485 | V13: 43156
I14: 2017 | L14: 8656 | M14: 8263 | N14: 1815 | P14: 8974 | Q14: 4767 | S14: 9424 | T14: 7327 | V14: 49226
A15: Q2: Total revenue made annually | I15: Grand Total | J15: 40545 | K15: 56708 | L15: 25877 | M15: 71260 | N15: 83718 | O15: 49998 | P15: 44727 | Q15: 10675 | R15: 46967 | S15: 48708 | T15: 13637 | U15: 20051 | V15: 512871
A16: Year | B16: Total Annual Revenue
A17: 2010 | B17: 19186025
A18: 2011 | B18: 11129166
A19: 2012 | B19: 31898645
A20: 2013 | B20: 20330449
A21: 2014 | B21: 16630214
A22: 2015 | B22: 12427983
A23: 2016 | B23: 12372867
A24: 2017 | B24: 13373420
A25: Grand Total | B25: 1.3734877e+08
P27: Q6: Profit margin By Items
A28: Q4: Contribution rate by region | P28: Row Labels | Q28: Revenue Total | R28: Cost Total | S28: Profit (RT - CT) | T28: Profit_margin
A29: Region | B29: Annual Revenue Contribution Rate | I29: Q5: Top 3 Product By Units sold | P29: Baby Food | Q29: 10350328 | R29: 6463683.9 | S29: 3886643.7 | T29: 0.37550924
A30: Sub-Saharan Africa | B30: 0.28884155 | I30: Items | J30: Total Units Sold | P30: Beverages | Q30: 2690794.6 | R30: 1802747.3 | S30: 888047.28 | T30: 0.33003161
A31: Europe | B31: 0.24295036 | I31: Cosmetics | J31: 83718 | P31: Cereal | Q31: 5322898.9 | R31: 3030455.5 | S31: 2292443.4 | T31: 0.43067574
A32: Asia | B32: 0.15542252 | I32: Clothes | J32: 71260 | P32: Clothes | Q32: 7787292.8 | R32: 2553958.4 | S32: 5233334.4 | T32: 0.67203514
A33: Australia and Oceania | B33: 0.10261661 | I33: Beverages | J33: 56708 | P33: Cosmetics | Q33: 36601510 | R33: 22045461 | S33: 14556049 | T33: 0.39768984
A34: Middle East and North Africa | B34: 0.10231403 | I34: Grand Total | J34: 211686 | P34: Fruits | Q34: 466481.34 | R34: 345986.16 | S34: 120495.18 | T34: 0.25830654
A35: Central America and the Caribbean | B35: 0.066767148 | P35: Household | Q35: 29889712 | R35: 22477107 | S35: 7412605.7 | T35: 0.24799856
A36: North America | B36: 0.041087784 | P36: Meat | Q36: 4503675.8 | R36: 3893065.8 | S36: 610610 | T36: 0.13558036
A37: Grand Total | B37: 1 | P37: Office Supplies | Q37: 30585380 | R37: 24655796 | S37: 5929583.8 | T37: 0.19386987
P38: Personal Care | Q38: 3980904.8 | R38: 2760282.4 | S38: 1220622.5 | T38: 0.30661936
P39: Snacks | Q39: 2080733.5 | R39: 1328789.3 | S39: 751944.18 | T39: 0.36138419
P40: Vegetables | Q40: 3089057.1 | R40: 1823237.4 | S40: 1265819.6 | T40: 0.40977541
A42: Q7: Average amount of Annual Profit
A43: Year | B43: Sum of Total Profit | C43: Avg. Annual Profit | D43: Performance | I43: Q8a: Top 4 Countries By Revenue
...

Sheet KPI_7
A1: Year | B1: Sum of Total Profit | C1: Avg. Annual Profit
A2: 2010 | B2: 6629567.4 | C2: =AVERAGEA(B2:B9) -> 5521024.8
A3: 2011 | B3: 2741008.2 | C3: =AVERAGEA(B2:B10) -> 5521024.8
A4: 2012 | B4: 9213010.1 | C4: =AVERAGEA(B2:B11) -> 5521024.8
A5: 2013 | B5: 6715420 | C5: =AVERAGEA(B2:B12) -> 5521024.8
A6: 2014 | B6: 5879461.7 | C6: =AVERAGEA(B2:B13) -> 5521024.8
A7: 2015 | B7: 3996539.4 | C7: =AVERAGEA(B2:B14) -> 5521024.8
A8: 2016 | B8: 4903838 | C8: =AVERAGEA(B2:B15) -> 5521024.8
A9: 2017 | B9: 4089353.5 | C9: =AVERAGEA(B2:B16) -> 5521024.8

Sheet Test Cal.
G1: Order Year | H1: Revenue Total | I1: Order Id Count | J1: A.C.V/A.O.V | K1: Year On Year Growth
B2: {=_xlfn.UNIQUE('Sample_Sales Records'!I:I)} -> Order Year | C2: Revenue Total | D2: Order Id count | E2: A.O.V | G2: {=_xlfn._xlws.SORT(B3:E10,1,1)} -> 2010 | H2: 19186025 | I2: 10 | J2: 1918602.5
B3: 2010 | C3: {=SUMIF(In.[Order Year],'Test Cal.'!B3:B11,In.[Total Revenue])} -> 19186025 | D3: {=COUNTIF(In.[Order Year],'Test Cal.'!B3:B11)} -> 10 | E3: =C3/D3 -> 1918602.5 | G3: 2011 | H3: 11129166 | I3: 12 | J3: 927430.51 | K3: =($H3-$H2)/$H2 -> -0.41993372
B4: 2012 | C4: 31898645 | D4: 22 | E4: =C4/D4 -> 1449938.4 | G4: 2012 | H4: 31898645 | I4: 22 | J4: 1449938.4 | K4: =($H4-$H3)/$H3 -> 1.8662206
B5: 2014 | C5: 16630214 | D5: 15 | E5: =C5/D5 -> 1108681 | G5: 2013 | H5: 20330449 | I5: 12 | J5: 1694204.1 | K5: =($H5-$H4)/$H4 -> -0.36265478
B6: 2013 | C6: 20330449 | D6: 12 | E6: =C6/D6 -> 1694204.1 | G6: 2014 | H6: 16630214 | I6: 15 | J6: 1108681 | K6: =($H6-$H5)/$H5 -> -0.18200455
B7: 2015 | C7: 12427983 | D7: 11 | E7: =C7/D7 -> 1129816.6 | G7: 2015 | H7: 12427983 | I7: 11 | J7: 1129816.6 | K7: =($H7-$H6)/$H6 -> -0.25268655
B8: 2011 | C8: 11129166 | D8: 12 | E8: =C8/D8 -> 927430.51 | G8: 2016 | H8: 12372867 | I8: 10 | J8: 1237286.7 | K8: =($H8-$H7)/$H7 -> -0.0044348017
B9: 2017 | C9: 13373420 | D9: 8 | E9: =C9/D9 -> 1671677.5 | G9: 2017 | H9: 13373420 | I9: 8 | J9: 1671677.5 | K9: =($H9-$H8)/$H8 -> 0.080866657
B10: 2016 | C10: 12372867 | D10: 10 | E10: =C10/D10 -> 1237286.7 | H10: =SUM(H2:H9) -> 1.3734877e+08
B11: 0 | C11: 0 | D11: 0 | E11: =C11/D11 -> #DIV/0!
G13: {=_xlfn.UNIQUE('Sample_Sales Records'!A:A)} -> Region | H13: Revenue Total | I13: Contribution Rate
G14: Australia and Oceania | H14: {=SUMIF('Sample_Sales Records'!A:A,'Test Cal.'!G14:G21,'Sample_Sales Records'!P:P)} -> 14094265 | I14: =H14/$H$22 -> 0.10261661
G15: Central America and the Caribbean | H15: 9170385.5 | I15: =H15/$H$22 -> 0.066767148
G16: Europe | H16: 33368932 | I16: =H16/$H$22 -> 0.24295036
G17: Sub-Saharan Africa | H17: 39672031 | I17: =H17/$H$22 -> 0.28884155
G18: Asia | H18: 21347091 | I18: =H18/$H$22 -> 0.15542252
G19: Middle East and North Africa | H19: 14052707 | I19: =H19/$H$22 -> 0.10231403
G20: North America | H20: 5643356.6 | I20: =H20/$H$22 -> 0.041087784
G21: 0 | H21: 0
H22: =SUM(H14:H20) -> 1.3734877e+08 | I22: =SUM(I14:I20) -> 1
G25: Items | H25: Revenue | I25: Cost | J25: Profit (Calculated) | K25: Profit (Derived) | L25: Profit Margin
G26: {=_xlfn.UNIQUE(In.[Item Type])} -> Baby Food | H26: {=SUMIF(In.[Item Type],_xlfn.ANCHORARRAY('Test Cal.'!G26),In.[Total Revenue])} -> 10350328 | I26: {=SUMIF(In.[Item Type],_xlfn.ANCHORARRAY('Test Cal.'!G26),In.[Total Cost])} -> 6463683.9 | J26: =H26-I26 -> 3886643.7 | K26: {=SUMIF(In.[Item Type],_xlfn.ANCHORARRAY('Test Cal.'!G26),In.[Total Profit])} -> 3886643.7 | L26: =J26/H26 -> 0.37550924
G27: Cereal | H27: 5322898.9 | I27: 3030455.5 | J27: =H27-I27 -> 2292443.4 | K27: 2292443.4 | L27: =J27/H27 -> 0.43067574
G28: Office Supplies | H28: 30585380 | I28: 24655796 | J28: =H28-I28 -> 5929583.8 | K28: 5929583.8 | L28: =J28/H28 -> 0.19386987
G29: Fruits | H29: 466481.34 | I29: 345986.16 | J29: =H29-I29 -> 120495.18 | K29: 120495.18 | L29: =J29/H29 -> 0.25830654
G30: Household | H30: 29889712 | I30: 22477107 | J30: =H30-I30 -> 7412605.7 | K30: 7412605.7 | L30: =J30/H30 -> 0.24799856
G31: Vegetables | H31: 3089057.1 | I31: 1823237.4 | J31: =H31-I31 -> 1265819.6 | K31: 1265819.6 | L31: =J31/H31 -> 0.40977541
G32: Personal Care | H32: 3980904.8 | I32: 2760282.4 | J32: =H32-I32 -> 1220622.5 | K32: 1220622.5 | L32: =J32/H32 -> 0.30661936
G33: Clothes | H33: 7787292.8 | I33: 2553958.4 | J33: =H33-I33 -> 5233334.4 | K33: 5233334.4 | L33: =J33/H33 -> 0.67203514
G34: Cosmetics | H34: 36601510 | I34: 22045461 | J34: =H34-I34 -> 14556049 | K34: 14556049 | L34: =J34/H34 -> 0.39768984
G35: Beverages | H35: 2690794.6 | I35: 1802747.3 | J35: =H35-I35 -> 888047.28 | K35: 888047.28 | L35: =J35/H35 -> 0.33003161
G36: Meat | H36: 4503675.8 | I36: 3893065.8 | J36: =H36-I36 -> 610610 | K36: 610610 | L36: =J36/H36 -> 0.13558036
G37: Snacks | H37: 2080733.5 | I37: 1328789.3 | J37: =H37-I37 -> 751944.18 | K37: 751944.18 | L37: =J37/H37 -> 0.36138419
H38: =SUM(_xlfn.ANCHORARRAY(H26)) -> 1.3734877e+08
